<?xml version="1.0"?>
<robot name="NXA"
       xmlns:xi="http://www.w3.org/2001/XInclude">
  <link name="WAIST">
    <visual>
      <origin xyz="0 0 0" rpy="0 -0 0"/>
      <geometry>
        <mesh filename="file:///tmp/WAIST_mesh.dae" scale="1 1 1" />
      </geometry>
    </visual>
    <collision>
      <origin xyz="0 0 0" rpy="0 -0 0"/>
      <geometry>
        <mesh filename="file:///tmp/WAIST_mesh.dae" scale="1 1 1" />
      </geometry>
    </collision>
    <inertial>
      <mass value="0" />
      <origin xyz="0 0 0" rpy="0 -0 0"/>
      <inertia ixx="0" ixy="0" ixz="0" iyy="0" iyz="0" izz="0"/>
    </inertial>
  </link>
  <link name="CHEST_LINK0">
    <visual>
      <origin xyz="0 0 0.267" rpy="0 -0 0"/>
      <geometry>
        <mesh filename="file:///tmp/CHEST_LINK0_mesh.dae" scale="1 1 1" />
      </geometry>
    </visual>
    <collision>
      <origin xyz="0 0 0.267" rpy="0 -0 0"/>
      <geometry>
        <mesh filename="file:///tmp/CHEST_LINK0_mesh.dae" scale="1 1 1" />
      </geometry>
    </collision>
    <inertial>
      <mass value="0" />
      <origin xyz="0 0 0" rpy="0 -0 0"/>
      <inertia ixx="0" ixy="0" ixz="0" iyy="0" iyz="0" izz="0"/>
    </inertial>
  </link>
  <link name="HEAD_LINK0">
    <visual>
      <origin xyz="0 0 0.302" rpy="0 -0 0"/>
      <geometry>
        <mesh filename="file:///tmp/HEAD_LINK0_mesh.dae" scale="1 1 1" />
      </geometry>
    </visual>
    <collision>
      <origin xyz="0 0 0.302" rpy="0 -0 0"/>
      <geometry>
        <mesh filename="file:///tmp/HEAD_LINK0_mesh.dae" scale="1 1 1" />
      </geometry>
    </collision>
    <inertial>
      <mass value="0" />
      <origin xyz="0 0 0" rpy="0 -0 0"/>
      <inertia ixx="0" ixy="0" ixz="0" iyy="0" iyz="0" izz="0"/>
    </inertial>
  </link>
  <link name="HEAD_LINK1">
    <visual>
      <origin xyz="0 0 0.08" rpy="0 -0 0"/>
      <geometry>
        <mesh filename="file:///tmp/HEAD_LINK1_mesh.dae" scale="1 1 1" />
      </geometry>
    </visual>
    <collision>
      <origin xyz="0 0 0.08" rpy="0 -0 0"/>
      <geometry>
        <mesh filename="file:///tmp/HEAD_LINK1_mesh.dae" scale="1 1 1" />
      </geometry>
    </collision>
    <inertial>
      <mass value="0" />
      <origin xyz="0 0 0" rpy="0 -0 0"/>
      <inertia ixx="0" ixy="0" ixz="0" iyy="0" iyz="0" izz="0"/>
    </inertial>
  </link>
  <link name="LARM_LINK0">
    <visual>
      <origin xyz="0.04 0.135 0.1015" rpy="0 -0 0"/>
      <geometry>
        <mesh filename="file:///tmp/LARM_LINK0_mesh.dae" scale="1 1 1" />
      </geometry>
    </visual>
    <collision>
      <origin xyz="0.04 0.135 0.1015" rpy="0 -0 0"/>
      <geometry>
        <mesh filename="file:///tmp/LARM_LINK0_mesh.dae" scale="1 1 1" />
      </geometry>
    </collision>
    <inertial>
      <mass value="0" />
      <origin xyz="0 0 0" rpy="0 -0 0"/>
      <inertia ixx="0" ixy="0" ixz="0" iyy="0" iyz="0" izz="0"/>
    </inertial>
  </link>
  <link name="LARM_LINK1">
    <visual>
      <origin xyz="0 0 0.066" rpy="0 -0 0"/>
      <geometry>
        <mesh filename="file:///tmp/LARM_LINK1_mesh.dae" scale="1 1 1" />
      </geometry>
    </visual>
    <collision>
      <origin xyz="0 0 0.066" rpy="0 -0 0"/>
      <geometry>
        <mesh filename="file:///tmp/LARM_LINK1_mesh.dae" scale="1 1 1" />
      </geometry>
    </collision>
    <inertial>
      <mass value="0" />
      <origin xyz="0 0 0" rpy="0 -0 0"/>
      <inertia ixx="0" ixy="0" ixz="0" iyy="0" iyz="0" izz="0"/>
    </inertial>
  </link>
  <link name="LARM_LINK2">
    <visual>
      <origin xyz="0 0.095 -0.25" rpy="0 -0 0"/>
      <geometry>
        <mesh filename="file:///tmp/LARM_LINK2_mesh.dae" scale="1 1 1" />
      </geometry>
    </visual>
    <collision>
      <origin xyz="0 0.095 -0.25" rpy="0 -0 0"/>
      <geometry>
        <mesh filename="file:///tmp/LARM_LINK2_mesh.dae" scale="1 1 1" />
      </geometry>
    </collision>
    <inertial>
      <mass value="0" />
      <origin xyz="0 0 0" rpy="0 -0 0"/>
      <inertia ixx="0" ixy="0" ixz="0" iyy="0" iyz="0" izz="0"/>
    </inertial>
  </link>
  <link name="LARM_LINK3">
    <visual>
      <origin xyz="0.1805 0 -0.03" rpy="0 -0 0"/>
      <geometry>
        <mesh filename="file:///tmp/LARM_LINK3_mesh.dae" scale="1 1 1" />
      </geometry>
    </visual>
    <collision>
      <origin xyz="0.1805 0 -0.03" rpy="0 -0 0"/>
      <geometry>
        <mesh filename="file:///tmp/LARM_LINK3_mesh.dae" scale="1 1 1" />
      </geometry>
    </collision>
    <inertial>
      <mass value="0" />
      <origin xyz="0 0 0" rpy="0 -0 0"/>
      <inertia ixx="0" ixy="0" ixz="0" iyy="0" iyz="0" izz="0"/>
    </inertial>
  </link>
  <link name="LARM_LINK4">
    <visual>
      <origin xyz="0.1495 0 0" rpy="0 -0 0"/>
      <geometry>
        <mesh filename="file:///tmp/LARM_LINK4_mesh.dae" scale="1 1 1" />
      </geometry>
    </visual>
    <collision>
      <origin xyz="0.1495 0 0" rpy="0 -0 0"/>
      <geometry>
        <mesh filename="file:///tmp/LARM_LINK4_mesh.dae" scale="1 1 1" />
      </geometry>
    </collision>
    <inertial>
      <mass value="0" />
      <origin xyz="0 0 0" rpy="0 -0 0"/>
      <inertia ixx="0" ixy="0" ixz="0" iyy="0" iyz="0" izz="0"/>
    </inertial>
  </link>
  <link name="LARM_LINK5">
    <visual>
      <origin xyz="0 0 -0.1335" rpy="0 -0 0"/>
      <geometry>
        <mesh filename="file:///tmp/LARM_LINK5_mesh.dae" scale="1 1 1" />
      </geometry>
    </visual>
    <collision>
      <origin xyz="0 0 -0.1335" rpy="0 -0 0"/>
      <geometry>
        <mesh filename="file:///tmp/LARM_LINK5_mesh.dae" scale="1 1 1" />
      </geometry>
    </collision>
    <inertial>
      <mass value="0" />
      <origin xyz="0 0 0" rpy="0 -0 0"/>
      <inertia ixx="0" ixy="0" ixz="0" iyy="0" iyz="0" izz="0"/>
    </inertial>
  </link>
  <link name="RARM_LINK0">
    <visual>
      <origin xyz="0.04 -0.135 0.1015" rpy="0 -0 0"/>
      <geometry>
        <mesh filename="file:///tmp/RARM_LINK0_mesh.dae" scale="1 1 1" />
      </geometry>
    </visual>
    <collision>
      <origin xyz="0.04 -0.135 0.1015" rpy="0 -0 0"/>
      <geometry>
        <mesh filename="file:///tmp/RARM_LINK0_mesh.dae" scale="1 1 1" />
      </geometry>
    </collision>
    <inertial>
      <mass value="0" />
      <origin xyz="0 0 0" rpy="0 -0 0"/>
      <inertia ixx="0" ixy="0" ixz="0" iyy="0" iyz="0" izz="0"/>
    </inertial>
  </link>
  <link name="RARM_LINK1">
    <visual>
      <origin xyz="0 0 0.066" rpy="0 -0 0"/>
      <geometry>
        <mesh filename="file:///tmp/RARM_LINK1_mesh.dae" scale="1 1 1" />
      </geometry>
    </visual>
    <collision>
      <origin xyz="0 0 0.066" rpy="0 -0 0"/>
      <geometry>
        <mesh filename="file:///tmp/RARM_LINK1_mesh.dae" scale="1 1 1" />
      </geometry>
    </collision>
    <inertial>
      <mass value="0" />
      <origin xyz="0 0 0" rpy="0 -0 0"/>
      <inertia ixx="0" ixy="0" ixz="0" iyy="0" iyz="0" izz="0"/>
    </inertial>
  </link>
  <link name="RARM_LINK2">
    <visual>
      <origin xyz="0 -0.095 -0.25" rpy="0 -0 0"/>
      <geometry>
        <mesh filename="file:///tmp/RARM_LINK2_mesh.dae" scale="1 1 1" />
      </geometry>
    </visual>
    <collision>
      <origin xyz="0 -0.095 -0.25" rpy="0 -0 0"/>
      <geometry>
        <mesh filename="file:///tmp/RARM_LINK2_mesh.dae" scale="1 1 1" />
      </geometry>
    </collision>
    <inertial>
      <mass value="0" />
      <origin xyz="0 0 0" rpy="0 -0 0"/>
      <inertia ixx="0" ixy="0" ixz="0" iyy="0" iyz="0" izz="0"/>
    </inertial>
  </link>
  <link name="RARM_LINK3">
    <visual>
      <origin xyz="0.1805 0 -0.03" rpy="0 -0 0"/>
      <geometry>
        <mesh filename="file:///tmp/RARM_LINK3_mesh.dae" scale="1 1 1" />
      </geometry>
    </visual>
    <collision>
      <origin xyz="0.1805 0 -0.03" rpy="0 -0 0"/>
      <geometry>
        <mesh filename="file:///tmp/RARM_LINK3_mesh.dae" scale="1 1 1" />
      </geometry>
    </collision>
    <inertial>
      <mass value="0" />
      <origin xyz="0 0 0" rpy="0 -0 0"/>
      <inertia ixx="0" ixy="0" ixz="0" iyy="0" iyz="0" izz="0"/>
    </inertial>
  </link>
  <link name="RARM_LINK4">
    <visual>
      <origin xyz="0.1495 0 0" rpy="0 -0 0"/>
      <geometry>
        <mesh filename="file:///tmp/RARM_LINK4_mesh.dae" scale="1 1 1" />
      </geometry>
    </visual>
    <collision>
      <origin xyz="0.1495 0 0" rpy="0 -0 0"/>
      <geometry>
        <mesh filename="file:///tmp/RARM_LINK4_mesh.dae" scale="1 1 1" />
      </geometry>
    </collision>
    <inertial>
      <mass value="0" />
      <origin xyz="0 0 0" rpy="0 -0 0"/>
      <inertia ixx="0" ixy="0" ixz="0" iyy="0" iyz="0" izz="0"/>
    </inertial>
  </link>
  <link name="RARM_LINK5">
    <visual>
      <origin xyz="0 0 -0.1335" rpy="0 -0 0"/>
      <geometry>
        <mesh filename="file:///tmp/RARM_LINK5_mesh.dae" scale="1 1 1" />
      </geometry>
    </visual>
    <collision>
      <origin xyz="0 0 -0.1335" rpy="0 -0 0"/>
      <geometry>
        <mesh filename="file:///tmp/RARM_LINK5_mesh.dae" scale="1 1 1" />
      </geometry>
    </collision>
    <inertial>
      <mass value="0" />
      <origin xyz="0 0 0" rpy="0 -0 0"/>
      <inertia ixx="0" ixy="0" ixz="0" iyy="0" iyz="0" izz="0"/>
    </inertial>
  </link>
  <joint name="CHEST_JOINT0" type="revolute">
    <parent link="WAIST"/>
    <child  link="CHEST_LINK0"/>
    <origin xyz="0 0 0.267" rpy="0 -0 0 "/>
    <axis   xyz="0 0 1"/>
    <limit lower="-3.14159" upper="3.14159" effort="100" velocity="2.51327" />
    <dynamics damping="0.2" friction="0" />
  </joint>
  <joint name="HEAD_JOINT0" type="revolute">
    <parent link="CHEST_LINK0"/>
    <child  link="HEAD_LINK0"/>
    <origin xyz="0 0 0.302" rpy="0 -0 0 "/>
    <axis   xyz="0 0 1"/>
    <limit lower="-1.22173" upper="1.22173" effort="100" velocity="6.68461" />
    <dynamics damping="0.2" friction="0" />
  </joint>
  <joint name="HEAD_JOINT1" type="revolute">
    <parent link="HEAD_LINK0"/>
    <child  link="HEAD_LINK1"/>
    <origin xyz="0 0 0.08" rpy="0 -0 0 "/>
    <axis   xyz="0 1 0"/>
    <limit lower="-0.401426" upper="1.309" effort="100" velocity="6.68461" />
    <dynamics damping="0.2" friction="0" />
  </joint>
  <joint name="LARM_JOINT0" type="revolute">
    <parent link="CHEST_LINK0"/>
    <child  link="LARM_LINK0"/>
    <origin xyz="0.04 0.135 0.1015" rpy="0 -0 0 "/>
    <axis   xyz="0 0 1"/>
    <limit lower="-1.5708" upper="1.5708" effort="100" velocity="3.89208" />
    <dynamics damping="0.2" friction="0" />
  </joint>
  <joint name="LARM_JOINT1" type="revolute">
    <parent link="LARM_LINK0"/>
    <child  link="LARM_LINK1"/>
    <origin xyz="0 0 0.066" rpy="0 -0 0 "/>
    <axis   xyz="0 1 0"/>
    <limit lower="-2.44346" upper="1.0472" effort="100" velocity="2.42601" />
    <dynamics damping="0.2" friction="0" />
  </joint>
  <joint name="LARM_JOINT2" type="revolute">
    <parent link="LARM_LINK1"/>
    <child  link="LARM_LINK2"/>
    <origin xyz="0 0.095 -0.25" rpy="0 -0 0 "/>
    <axis   xyz="0 1 0"/>
    <limit lower="-1.22173" upper="1.5708" effort="100" velocity="3.63028" />
    <dynamics damping="0.2" friction="0" />
  </joint>
  <joint name="LARM_JOINT3" type="revolute">
    <parent link="LARM_LINK2"/>
    <child  link="LARM_LINK3"/>
    <origin xyz="0.1805 0 -0.03" rpy="0 -0 0 "/>
    <axis   xyz="1 0 0"/>
    <limit lower="-3.14159" upper="1.74533" effort="100" velocity="6.353" />
    <dynamics damping="0.2" friction="0" />
  </joint>
  <joint name="LARM_JOINT4" type="revolute">
    <parent link="LARM_LINK3"/>
    <child  link="LARM_LINK4"/>
    <origin xyz="0.1495 0 0" rpy="0 -0 0 "/>
    <axis   xyz="0 1 0"/>
    <limit lower="-3.57792" upper="1.13446" effort="100" velocity="6.353" />
    <dynamics damping="0.2" friction="0" />
  </joint>
  <joint name="LARM_JOINT5" type="revolute">
    <parent link="LARM_LINK4"/>
    <child  link="LARM_LINK5"/>
    <origin xyz="0 0 -0.1335" rpy="0 -0 0 "/>
    <axis   xyz="0 0 1"/>
    <limit lower="-4.71239" upper="4.71239" effort="100" velocity="6.353" />
    <dynamics damping="0.2" friction="0" />
  </joint>
  <joint name="RARM_JOINT0" type="revolute">
    <parent link="CHEST_LINK0"/>
    <child  link="RARM_LINK0"/>
    <origin xyz="0.04 -0.135 0.1015" rpy="0 -0 0 "/>
    <axis   xyz="0 0 1"/>
    <limit lower="-1.5708" upper="1.5708" effort="100" velocity="3.89208" />
    <dynamics damping="0.2" friction="0" />
  </joint>
  <joint name="RARM_JOINT1" type="revolute">
    <parent link="RARM_LINK0"/>
    <child  link="RARM_LINK1"/>
    <origin xyz="0 0 0.066" rpy="0 -0 0 "/>
    <axis   xyz="0 1 0"/>
    <limit lower="-2.44346" upper="1.0472" effort="100" velocity="2.42601" />
    <dynamics damping="0.2" friction="0" />
  </joint>
  <joint name="RARM_JOINT2" type="revolute">
    <parent link="RARM_LINK1"/>
    <child  link="RARM_LINK2"/>
    <origin xyz="0 -0.095 -0.25" rpy="0 -0 0 "/>
    <axis   xyz="0 1 0"/>
    <limit lower="-1.22173" upper="1.5708" effort="100" velocity="3.63028" />
    <dynamics damping="0.2" friction="0" />
  </joint>
  <joint name="RARM_JOINT3" type="revolute">
    <parent link="RARM_LINK2"/>
    <child  link="RARM_LINK3"/>
    <origin xyz="0.1805 0 -0.03" rpy="0 -0 0 "/>
    <axis   xyz="1 0 0"/>
    <limit lower="-1.74533" upper="3.14159" effort="100" velocity="6.353" />
    <dynamics damping="0.2" friction="0" />
  </joint>
  <joint name="RARM_JOINT4" type="revolute">
    <parent link="RARM_LINK3"/>
    <child  link="RARM_LINK4"/>
    <origin xyz="0.1495 0 0" rpy="0 -0 0 "/>
    <axis   xyz="0 1 0"/>
    <limit lower="-3.57792" upper="1.13446" effort="100" velocity="6.353" />
    <dynamics damping="0.2" friction="0" />
  </joint>
  <joint name="RARM_JOINT5" type="revolute">
    <parent link="RARM_LINK4"/>
    <child  link="RARM_LINK5"/>
    <origin xyz="0 0 -0.1335" rpy="0 -0 0 "/>
    <axis   xyz="0 0 1"/>
    <limit lower="-4.71239" upper="4.71239" effort="100" velocity="6.353" />
    <dynamics damping="0.2" friction="0" />
  </joint>
</robot>
